Workbook
Name Print_Titles: 사진대지!$9:$12

Sheet 데이터
A4: 기준정보 입력
A6: 회사명 : ㈜매그나텍
A7: 모델명 | B7: 규격 | C7: 단가 | D7: 분류번호 | E7: 카테고리 | F7: 분류1 | G7: 분류2 | H7: 분류3 (모델명) | I7: 분류4 (와트수) | J7: 본/개 | K7: 분류5 (기타) | L7: 분류6 (기타)
A8: MT-SLC-075 | B8: =IF($G8="","-",CONCATENATE(F8," ",G8," ",H8," ",I8," ",K8," ",L8)) -> LED가로등기구 MT-SLC-075 75W | C8: 340000 | D8: 39111603 | E8: 도로조명설비 | G8: LED가로등기구 | H8: MT-SLC-075 | I8: 75W | J8: 개
A9: MT-SLC-100 | B9: =IF($G9="","-",CONCATENATE(F9," ",G9," ",H9," ",I9," ",K9," ",L9)) -> LED가로등기구 MT-SLC-100 100W | C9: 414000 | D9: 39111603 | E9: 도로조명설비 | G9: LED가로등기구 | H9: MT-SLC-100 | I9: 100W | J9: 개
A10: MT-SLC-125 | B10: =IF($G10="","-",CONCATENATE(F10," ",G10," ",H10," ",I10," ",K10," ",L10)) -> LED가로등기구 MT-SLC-125 125W | C10: 440000 | D10: 39111603 | E10: 도로조명설비 | G10: LED가로등기구 | H10: MT-SLC-125 | I10: 125W | J10: 개
A11: MT-SLC-025-35 | B11: =IF($G11="","-",CONCATENATE(F11," ",G11," ",H11," ",I11," ",K11," ",L11)) -> LED보안등기구 MT-SLC-025-35 25W | C11: 203000 | D11: 39111608 | E11: 거주로조명설비 | G11: LED보안등기구 | H11: MT-SLC-025-35 | I11: 25W | J11: 개
A12: MT-SLA-100 | B12: =IF($G12="","-",CONCATENATE(F12," ",G12," ",H12," ",I12," ",K12," ",L12)) -> LED가로등기구 MT-SLA-100 100W | C12: 381000 | D12: 39111603 | E12: 도로조명설비 | G12: LED가로등기구 | H12: MT-SLA-100 | I12: 100W | J12: 개
A13: MT-SLA-150 | B13: =IF($G13="","-",CONCATENATE(F13," ",G13," ",H13," ",I13," ",K13," ",L13)) -> LED가로등기구 MT-SLA-150 150W | C13: 437000 | D13: 39111603 | E13: 도로조명설비 | G13: LED가로등기구 | H13: MT-SLA-150 | I13: 150W | J13: 개
A14: MT-SLC-150 | B14: =IF($G14="","-",CONCATENATE(F14," ",G14," ",H14," ",I14," ",K14," ",L14)) -> LED가로등기구 MT-SLC-150 150W | C14: 464000 | D14: 39111603 | E14: 도로조명설비 | G14: LED가로등기구 | H14: MT-SLC-150 | I14: 150W | J14: 개
A15: MT-SLA(D)-125 | B15: =IF($G15="","-",CONCATENATE(F15," ",G15," ",H15," ",I15," ",K15," ",L15)) -> LED가로등기구 MT-SLA(D)-125 125W | C15: 410000 | D15: 39111603 | E15: 도로조명설비 | G15: LED가로등기구 | H15: MT-SLA(D)-125 | I15: 125W | J15: 개
A16: MT-SLA(D)-150 | B16: =IF($G16="","-",CONCATENATE(F16," ",G16," ",H16," ",I16," ",K16," ",L16)) -> LED가로등기구 MT-SLA(D)-150 150W | C16: 450000 | D16: 39111603 | E16: 도로조명설비 | G16: LED가로등기구 | H16: MT-SLA(D)-150 | I16: 150W | J16: 개
A17: MT-SLA(D)-100 | B17: =IF($G17="","-",CONCATENATE(F17," ",G17," ",H17," ",I17," ",K17," ",L17)) -> LED가로등기구 MT-SLA(D)-100 100W | C17: 377000 | D17: 39111603 | E17: 도로조명설비 | G17: LED가로등기구 | H17: MT-SLA(D)-100 | I17: 100W | J17: 개
A18: MT-SLC-030 | B18: =IF($G18="","-",CONCATENATE(F18," ",G18," ",H18," ",I18," ",K18," ",L18)) -> LED보안등기구 MT-SLC-030 30W | C18: 220000 | D18: 39111608 | E18: 거주로조명설비 | G18: LED보안등기구 | H18: MT-SLC-030 | I18: 30W | J18: 개
A19: MT-SLC-040 | B19: =IF($G19="","-",CONCATENATE(F19," ",G19," ",H19," ",I19," ",K19," ",L19)) -> LED보안등기구 MT-SLC-040 40W | C19: 265000 | D19: 39111608 | E19: 거주로조명설비 | G19: LED보안등기구 | H19: MT-SLC-040 | I19: 40W | J19: 개
A20: MT-SLC-050 | B20: =IF($G20="","-",CONCATENATE(F20," ",G20," ",H20," ",I20," ",K20," ",L20)) -> LED보안등기구 MT-SLC-050 50W | C20: 270000 | D20: 39111608 | E20: 거주로조명설비 | G20: LED보안등기구 | H20: MT-SLC-050 | I20: 50W | J20: 개
... A31: MTSOLAR-50B | B31: =IF($G31="","-",CONCATENATE(F31," ",G31," ",H31," ",I31," ",K31," ",L31)) -> 태양광가로등 MTSOLAR-50B 50W | C31: 4950000 | D31: 39111697 | E31: 신재생에너지가로등 | G31: 태양광가로등 | H31: MTSOLAR-50B | I31: 50W | J31: 개
A32: MT-VB | B32: =IF($G32="","-",CONCATENATE(F32," ",G32," ",H32," ",I32," ",K32," ",L32)) -> LED투광등기구 (부품)매그나텍 MT-VB 눈부심방지장치 | C32: 250000 | D32: 39111611 | E32: 투광조명 | G32: LED투광등기구 | H32: (부품)매그나텍 | I32: MT-VB | J32: 개 | K32: 눈부심방지장치
A33: MT-VM | B33: =IF($G33="","-",CONCATENATE(F33," ",G33," ",H33," ",I33," ",K33," ",L33)) -> LED투광등기구 (부품)매그나텍 MT-VM 눈부심방지장치 | C33: 200000 | D33: 39111611 | E33: 투광조명 | G33: LED투광등기구 | H33: (부품)매그나텍 | I33: MT-VM | J33: 개 | K33: 눈부심방지장치
A34: ARENA-200S | B34: =IF($G34="","-",CONCATENATE(F34," ",G34," ",H34," ",I34," ",K34," ",L34)) -> LED투광등기구 ARENA-200S 200W | C34: 1550000 | D34: 39111611 | E34: 투광조명 | G34: LED투광등기구 | H34: ARENA-200S | I34: 200W | J34: 개
A35: ARENA(M)-200S | B35: =IF($G35="","-",CONCATENATE(F35," ",G35," ",H35," ",I35," ",K35," ",L35)) -> LED투광등기구 ARENA(M)-200S 200W | C35: 1441460 | D35: 39111611 | E35: 투광조명 | G35: LED투광등기구 | H35: ARENA(M)-200S | I35: 200W | J35: 개
A36: ARENA-300S | B36: =IF($G36="","-",CONCATENATE(F36," ",G36," ",H36," ",I36," ",K36," ",L36)) -> LED투광등기구 ARENA-300S 300W | C36: 1950000 | D36: 39111611 | E36: 투광조명 | G36: LED투광등기구 | H36: ARENA-300S | I36: 300W | J36: 개
A37: ARENA(X)-600 | B37: =IF($G37="","-",CONCATENATE(F37," ",G37," ",H37," ",I37," ",K37," ",L37)) -> LED투광등기구 ARENA(X)-600 600W | C37: 2900000 | D37: 39111611 | E37: 투광조명 | G37: LED투광등기구 | H37: ARENA(X)-600 | I37: 600W | J37: 개
A38: ARENA-400(3000K) | B38: =IF($G38="","-",CONCATENATE(F38," ",G38," ",H38," ",I38," ",K38," ",L38)) -> LED투광등기구 ARENA-400(3000K) 400W | C38: 2370000 | D38: 39111611 | E38: 투광조명 | G38: LED투광등기구 | H38: ARENA-400(3000K) | I38: 400W | J38: 개
A39: ARENA-400 | B39: =IF($G39="","-",CONCATENATE(F39," ",G39," ",H39," ",I39," ",K39," ",L39)) -> LED투광등기구 ARENA-400 400W | C39: 2380000 | D39: 39111611 | E39: 투광조명 | G39: LED투광등기구 | H39: ARENA-400 | I39: 400W | J39: 개
A40: ARENA-400S | B40: =IF($G40="","-",CONCATENATE(F40," ",G40," ",H40," ",I40," ",K40," ",L40)) -> LED투광등기구 ARENA-400S 400W | C40: 2350000 | D40: 39111611 | E40: 투광조명 | G40: LED투광등기구 | H40: ARENA-400S | I40: 400W | J40: 개
A41: ARENA(M)-300S | B41: =IF($G41="","-",CONCATENATE(F41," ",G41," ",H41," ",I41," ",K41," ",L41)) -> LED투광등기구 ARENA(M)-300S 300W | C41: 1794000 | D41: 39111611 | E41: 투광조명 | G41: LED투광등기구 | H41: ARENA(M)-300S | I41: 300W | J41: 개
A42: ARENA(M)-400S | B42: =IF($G42="","-",CONCATENATE(F42," ",G42," ",H42," ",I42," ",K42," ",L42)) -> LED투광등기구 ARENA(M)-400S 400W | C42: 2185490 | D42: 39111611 | E42: 투광조명 | G42: LED투광등기구 | H42: ARENA(M)-400S | I42: 400W | J42: 개
A43: ARENA(M)-400 | B43: =IF($G43="","-",CONCATENATE(F43," ",G43," ",H43," ",I43," ",K43," ",L43)) -> LED투광등기구 ARENA(M)-400 400W | C43: 2208000 | D43: 39111611 | E43: 투광조명 | G43: LED투광등기구 | H43: ARENA(M)-400 | I43: 400W | J43: 개
A44: ARENA-500(3000K) | B44: =IF($G44="","-",CONCATENATE(F44," ",G44," ",H44," ",I44," ",K44," ",L44)) -> LED투광등기구 ARENA-500(3000K) 500W | C44: 2540000 | D44: 39111611 | E44: 투광조명 | G44: LED투광등기구 | H44: ARENA-500(3000K) | I44: 500W | J44: 개
A45: ARENA(M)-500, | B45: =IF($G45="","-",CONCATENATE(F45," ",G45," ",H45," ",I45," ",K45," ",L45)) -> LED투광등기구 ARENA(M)-500, 500W | C45: 2530000 | D45: 39111611 | E45: 투광조명 | G45: LED투광등기구 | H45: ARENA(M)-500, | I45: 500W | J45: 개
... A83: MTPS-708 | B83: =IF($G83="","-",CONCATENATE(F83," ",G83," ",H83," ",I83," ",K83," ",L83)) -> 가로등주부속자재 MTPS-708 암 | C83: 450000 | D83: 39111526 | E83: 가로등주및부속자재 | G83: 가로등주부속자재 | H83: MTPS-708 | I83: 암 | J83: 개
A84: MTPS-101-10 | B84: =IF($G84="","-",CONCATENATE(F84," ",G84," ",H84," ",I84," ",K84," ",L84)) -> 스테인리스가로등주 MTPS-101-10 10m 1등용 | C84: 1910000 | D84: 39111526 | E84: 가로등주및부속자재 | G84: 스테인리스가로등주 | H84: MTPS-101-10 | I84: 10m | J84: 본 | K84: 1등용
A85: MTPS-101-8 | B85: =IF($G85="","-",CONCATENATE(F85," ",G85," ",H85," ",I85," ",K85," ",L85)) -> 스테인리스가로등주 MTPS-101-8 8m 1등용 | C85: 1671000 | D85: 39111526 | E85: 가로등주및부속자재 | G85: 스테인리스가로등주 | H85: MTPS-101-8 | I85: 8m | J85: 본 | K85: 1등용
A86: MTPS-101-9 | B86: =IF($G86="","-",CONCATENATE(F86," ",G86," ",H86," ",I86," ",K86," ",L86)) -> 스테인리스가로등주 MTPS-101-9 9m 1등용 | C86: 1838000 | D86: 39111526 | E86: 가로등주및부속자재 | G86: 스테인리스가로등주 | H86: MTPS-101-9 | I86: 9m | J86: 본 | K86: 1등용
A87: MTPS-102-10 | B87: =IF($G87="","-",CONCATENATE(F87," ",G87," ",H87," ",I87," ",K87," ",L87)) -> 스테인리스가로등주 MTPS-102-10 10m 1등용 | C87: 2087000 | D87: 39111526 | E87: 가로등주및부속자재 | G87: 스테인리스가로등주 | H87: MTPS-102-10 | I87: 10m | J87: 본 | K87: 1등용
A88: MTPS-102-8 | B88: =IF($G88="","-",CONCATENATE(F88," ",G88," ",H88," ",I88," ",K88," ",L88)) -> 스테인리스가로등주 MTPS-102-8 8m 1등용 | C88: 1775000 | D88: 39111526 | E88: 가로등주및부속자재 | G88: 스테인리스가로등주 | H88: MTPS-102-8 | I88: 8m | J88: 본 | K88: 1등용
A89: MTPS-102-9 | B89: =IF($G89="","-",CONCATENATE(F89," ",G89," ",H89," ",I89," ",K89," ",L89)) -> 스테인리스가로등주 MTPS-102-9 9m 1등용 | C89: 1860000 | D89: 39111526 | E89: 가로등주및부속자재 | G89: 스테인리스가로등주 | H89: MTPS-102-9 | I89: 9m | J89: 본 | K89: 1등용
A90: MTPS-103-10 | B90: =IF($G90="","-",CONCATENATE(F90," ",G90," ",H90," ",I90," ",K90," ",L90)) -> 스테인리스가로등주 MTPS-103-10 10m 1등용 | C90: 2013000 | D90: 39111526 | E90: 가로등주및부속자재 | G90: 스테인리스가로등주 | H90: MTPS-103-10 | I90: 10m | J90: 본 | K90: 1등용
A91: MTPS-103-10-2 | B91: =IF($G91="","-",CONCATENATE(F91," ",G91," ",H91," ",I91," ",K91," ",L91)) -> 스테인리스가로등주 MTPS-103-10-2 10m 2등용 | C91: 2140000 | D91: 39111526 | E91: 가로등주및부속자재 | G91: 스테인리스가로등주 | H91: MTPS-103-10-2 | I91: 10m | J91: 본 | K91: 2등용
...

Sheet 기초 자료 입력
A4: [ 기초 DATA 입력 ]
A6: 회사명 : ㈜매그나텍
A7: 1. 계약정보 | B7: 계약건명 | C7: 수기 | D7: 울산공항 계류장조명등 개선공사 관급자재 구매
B8: 계약번호 | C8: 수기 | D8: R25TA00498993-00
B9: 계약일자 | C9: 수기 | D9: 46120
A11: 2. 납품정보 | B11: 납품요구번호 | C11: 수기 | D11: R26TB01782064-00
B12: 납품기한 | C12: 수기 | D12: 46196
A14: 3. 공문관련 | B14: 제출(납품)일자 | C14: 수기 | D14: 46195
B15: 공문마지막번호 | C15: 수기 | D15: 2
B16: 공문번호 | C16: 자동 | D16: =CONCATENATE("MT-",TEXT(D14,"yyyy"),TEXT(D14,"mm"),TEXT(D14,"dd"),IF(LEN(D15)<2,"0"&D15&"호",D15&"호")) -> MT-2026062202호
A18: 4. 발주사항 | B18: 발주처 | C18: 수기 | D18: 한국공항공사 울산공항
B19: 수요기관 번호 | C19: 수기 | D19: 6108524413
B20: 관청 구분 | C20: 선택 | D20: 기관
B21: 감리유무 | C21: 선택 | D21: 무
A23: 5. 물품 수 | B23: 1 ~ 10 中 선택 | C23: 선택 | D23: 1
J24: [ 자동작성 ] | M24: 수기
A25: 6. 제품정보 | B25: 계약액(원) | C25: No. | D25: 모델명 | E25: 단가 (원, VAT포함) | F25: 단위 | G25: 수량 | H25: 총액(VAT포함) | J25: 정부물품분류번호 | K25: 품명 및 규격 | L25: 물품명 | M25: 원산지
B26: [ 수기 입력 ] | C26: 1 | D26: ARENA-600(3000K) | E26: =IF(D26="","-",VLOOKUP($D26,데이터!$A$8:$K$289,3,0)) -> 2950000 | F26: =IF(E26="","-",VLOOKUP($D26,데이터!$A$8:$K$289,10,0)) -> 개 | G26: 28 | H26: =E26*G26 -> 82600000 | J26: =IF($D26="","-",VLOOKUP($D26,데이터!$A$8:$K$289,4,0)) -> 39111611 | K26: =IF($D26="","-",VLOOKUP($D26,데이터!$A$8:$K$289,2,0)) -> LED투광등기구 ARENA-600(3000K) 600W | L26: =IF($D26="","-",VLOOKUP($D26,데이터!$A$8:$K$289,5,0)) -> 투광조명 | M26: 대한민국
C27: 2 | D27: ARENA-600(3000K) | E27: =IF(D27="","-",VLOOKUP($D27,데이터!$A$8:$K$289,3,0)) -> 2950000 | F27: =IF(E27="","-",VLOOKUP($D27,데이터!$A$8:$K$289,10,0)) -> 개 | G27: 28 | H27: =E27*G27 -> 82600000 | J27: =IF($D27="","",VLOOKUP($D27,데이터!$A$8:$K$289,4,0)) -> 39111611 | K27: =IF($D27="","",VLOOKUP($D27,데이터!$A$8:$K$289,2,0)) -> LED투광등기구 ARENA-600(3000K) 600W | L27: =IF($D27="","",VLOOKUP($D27,데이터!$A$8:$K$289,5,0)) -> 투광조명 | M27: 대한민국
C28: 3 | D28: ARENA-600(3000K) | E28: =IF(D28="","-",VLOOKUP($D28,데이터!$A$8:$K$289,3,0)) -> 2950000 | F28: =IF(E28="","-",VLOOKUP($D28,데이터!$A$8:$K$289,10,0)) -> 개 | G28: 28 | H28: =E28*G28 -> 82600000 | J28: =IF($D28="","",VLOOKUP($D28,데이터!$A$8:$K$289,4,0)) -> 39111611 | K28: =IF($D28="","",VLOOKUP($D28,데이터!$A$8:$K$289,2,0)) -> LED투광등기구 ARENA-600(3000K) 600W | L28: =IF($D28="","",VLOOKUP($D28,데이터!$A$8:$K$289,5,0)) -> 투광조명 | M28: 대한민국
C29: 4 | D29: ARENA-600(3000K) | E29: =IF(D29="","-",VLOOKUP($D29,데이터!$A$8:$K$289,3,0)) -> 2950000 | F29: =IF(E29="","-",VLOOKUP($D29,데이터!$A$8:$K$289,10,0)) -> 개 | G29: 28 | H29: =E29*G29 -> 82600000 | J29: =IF($D29="","",VLOOKUP($D29,데이터!$A$8:$K$289,4,0)) -> 39111611 | K29: =IF($D29="","",VLOOKUP($D29,데이터!$A$8:$K$289,2,0)) -> LED투광등기구 ARENA-600(3000K) 600W | L29: =IF($D29="","",VLOOKUP($D29,데이터!$A$8:$K$289,5,0)) -> 투광조명 | M29: 대한민국
C30: 5 | H30: =E30*G30 -> 0
C31: 6 | H31: =E31*G31 -> 0
C32: 7 | H32: =E32*G32 -> 0
C33: 8 | H33: =E33*G33 -> 0
C34: 9 | H34: =E34*G34 -> 0
C35: 10 | H35: =E35*G35 -> 0
C36: 판매액 합계 | G36: =SUM(G26:G35) -> 112 | H36: =SUM(H26:H35) -> 330400000
A38: 7. 수수료 | B38: (원) | C38: 수기 | D38: 446040
B45: 수수료(원) - A | C45: 수기 | D45: =$D$38 -> 446040

Sheet 공문
A1: 건강한 에너지 건강한 빛 건강한 공기
A2: 주식회사 매그나텍
A4: 수신 | B4: ='기초 자료 입력'!D18 -> 한국공항공사 울산공항
A5: (경유)
A6: 제목 | B6: ='기초 자료 입력'!D7&" 건의 납품계 제출" -> 울산공항 계류장조명등 개선공사 관급자재 구매 건의 납품계 제출
A7: =CONCATENATE("1. 귀 ",'기초 자료 입력'!$D$20,"의 무궁한 발전을 기원 합니다.") -> 1. 귀 기관의 무궁한 발전을 기원 합니다.
A9: =CONCATENATE("2. ",'기초 자료 입력'!$D$7, "건의 납품을 완료하여") -> 2. 울산공항 계류장조명등 개선공사 관급자재 구매건의 납품을 완료하여
A10: 납품계를 제출하오니 처리하여 주시기 바랍니다.
A12: =CONCATENATE("가. 납품요구번호 : ",'기초 자료 입력'!D11) -> 가. 납품요구번호 : R26TB01782064-00
A13: 나. 계약금액 : | C13: ="금"&NUMBERSTRING('기초 자료 입력'!H36,1)&"원"&" (\"&TEXT('기초 자료 입력'!H36,"#,###")&")" -> #NAME?
A14: 다. 계약일자 : | C14: ='기초 자료 입력'!D9 -> 46120
A15: 라. 납품기한 : | C15: ='기초 자료 입력'!D12 -> 46196
A17: 붙임 납품계 1부. 끝.
A25: 주식회사 매그나텍 대표이사 박 선 후
A30: 담당 최한진 부장 이지훈 전무 채현병 대표 박선후
A31: 협조자
A32: 시행 매그나텍 | C32: ='기초 자료 입력'!D16 -> MT-2026062202호 | G32: 접수
A33: 우 57241 | C33: 전라남도 장성군 동화면 전자농공단지2길 55 | I33: / www.magnatech.co.kr
A34: 전화번호 061-392-5508 | D34: 팩스번호 061-392-5508 | H34: / sales@mgnt.kr

Sheet 납품계
A2: 납 품 계
D3: 감독관 확인 : (인)
A7: 1. 납품요구번호 : | B7: ='기초 자료 입력'!$D$11 -> R26TB01782064-00
A8: 2. 계 약 건 명 : | B8: ='기초 자료 입력'!$D$7 -> 울산공항 계류장조명등 개선공사 관급자재 구매
A9: 3. 계 약 금 액 : | B9: =공문!$C$13 -> #NAME?
A10: 4. 계 약 일 자 : | B10: ='기초 자료 입력'!$D$9 -> 46120
A11: 5. 납 품 기 한 : | B11: ='기초 자료 입력'!$D$12 -> 46196
A12: 6. 납 품 일 자 : | B12: ='기초 자료 입력'!$D$14 -> 46195
A14: 상기 계약건에 대해 납품을 완료하였기에 납품계를 제출합니다.
A17: 붙임 : 1. 분할납품요구서 1부.
A18: 붙임 : 2. 물품검사(수)내역서 1부.
A19: 붙임 : 3. 물품납품확인서 1부.
A20: 붙임 : 4. 사진대지 1부. 끝.
A23: =B12 -> 46195
J24: 계약자
C25: 납품자 | J25: 주 소 : 전남 장성군 동화면 전자농공단지2길 55
C26: 주 소 : | D26: 전남 장성군 동화면 전자농공단지2길 55 | J26: 업체명 : 주식회사 매그나텍
C27: 업체명 : | D27: 주식회사 매그나텍 | J27: 대표자 : 박 선 후 (인)
C28: 대표자 : | D28: 박 선 후 | E28: (인)
A33: =공문!B4&" 귀중" -> 한국공항공사 울산공항 귀중

Sheet 물납영수증
A2: 물 품 납 품 및 영 수 증
A4: 증 빙 번 호
A5: 계 약 번 호 | C5: =_xlfn.CONCAT('기초 자료 입력'!D8,"호") -> R25TA00498993-00호 | E5: 납품지시번호 | I5: ='기초 자료 입력'!D11 -> R26TB01782064-00 | J5: 납 품 기 한 | M5: =TEXT('기초 자료 입력'!D12,"yyyy. Mm. dd.") -> 2026. 06. 23.
A6: 계 약 일 자 | C6: =TEXT('기초 자료 입력'!D9,"yyyy. Mm. dd.") -> 2026. 04. 08. | E6: 납품지시일자 | I6: =TEXT('기초 자료 입력'!D9,"yyyy. Mm. dd.") -> 2026. 04. 08. | J6: 검사요청기한
A7: 수 요 기 관 | C7: ='기초 자료 입력'!D18 -> 한국공항공사 울산공항 | E7: 수요기관번호 | I7: ='기초 자료 입력'!D19 -> 6108524413 | J7: 회 계 명
A8: 계약(납품요구)금액 | C8: =J41 -> 2.478e+08 | E8: 지 체 상 금 | J8: 지 체 일 수
A9: 감 가 액 | E9: 선 금 | J9: 지 급 액 | M9: =J41 -> 2.478e+08
A10: 물 품 대 | C10: =J41 -> 2.478e+08 | E10: 수 수 료 | I10: ='기초 자료 입력'!D45 -> 446040 | J10: 징 수 결 정 액 | M10: =SUM(C10,I10) -> 2.4824604e+08
A11: 조달청등록번호 | I11: 계약 상대자 신청검사장소
A14: 아래물품을 납품하고자 하오니 인수하여 주시기 | I14: 아래물품은 검사결과 합격판정이 되었음을 증명함
A15: 바랍니다.
C16: ='기초 자료 입력'!D14 -> 46195 | I16: 검사요청일 | J16: =C16 -> 46195
A17: 주 소 : 전남 장성군 동화면 전자농공단지2길 55
A18: 상 호 : (주)매그나텍 | I18: 검사보완일 | J18: 년 월 일
I19: (검사불합격시 기재)
A20: 대표자 : 박 선 후 󰄫 (전화 : 061-392-5508) | I20: 검사합격일 | J20: 년 월 일
A22: ※ 단체수의계약 물품의 경우 | I22: 검사완료일 | J22: 년 월 일
A23: 납품업체명 :
A24: 대 표 자 : 󰄫 | I24: 소속검사관 | K24: 󰄫
A26: 수요기관 물품출납 공무원 영수인에 의하여 아래 | I26: 아래물품을 정히 영수함.
A27: 물품이 납품되었음을 확인함. | I27: 수요기관 전화번호 :
C29: 년 월 일 | I29: 검수요청일 | J29: 년 월 일
I30: 검수완료일 | J30: 년 월 일
B31: 조달청확인자 | G31: 󰄫 | I31: 소 속
I32: 출납공무원 | K32: 󰄫
A34: 순번 | B34: 정부물품분류번호 | D34: 품명 및 | F34: 단위 | H34: 수량 | I34: 단 가 | J34: 금 액 | O34: 원 산 지
D35: 규 격
A36: 1 | B36: =VLOOKUP('기초 자료 입력'!D26,데이터!$A$8:$E$139,4,0) -> 39111611 | D36: =VLOOKUP('기초 자료 입력'!D26,데이터!$A$8:$E$139,2,0) -> LED투광등기구 ARENA-600(3000K) 600W | F36: =검수내역서!C7 -> 개 | H36: =검수내역서!E7 -> 28 | I36: =검수내역서!D7 -> 2950000 | J36: =H36*I36 -> 82600000 | O36: =IF(D36="","","대한민국") -> 대한민국
A37: =IF(B37="","","2") -> 2 | B37: =IF(ISERROR(VLOOKUP('기초 자료 입력'!D27,데이터!$A$8:$E$139,4,0)),"",VLOOKUP('기초 자료 입력'!D27,데이터!$A$8:$E$139,4,0)) -> 39111611 | D37: =IF(ISERROR(VLOOKUP('기초 자료 입력'!D27,데이터!$A$8:$E$139,2,0)),"",VLOOKUP('기초 자료 입력'!D27,데이터!$A$8:$E$139,2,0)) -> LED투광등기구 ARENA-600(3000K) 600W | F37: =IF('기초 자료 입력'!F27="","",'기초 자료 입력'!F27) -> 개 | H37: =IF('기초 자료 입력'!G27="","",'기초 자료 입력'!G27) -> 28 | I37: =IF('기초 자료 입력'!E27="","",'기초 자료 입력'!E27) -> 2950000 | J37: =IF(B37="","",H37*I37) -> 82600000 | O37: =IF(D37="","","대한민국") -> 대한민국
A38: =IF(B38="","","3") -> 3 | B38: =IF(ISERROR(VLOOKUP('기초 자료 입력'!D28,데이터!$A$8:$E$139,4,0)),"",VLOOKUP('기초 자료 입력'!D28,데이터!$A$8:$E$139,4,0)) -> 39111611 | D38: =IF(ISERROR(VLOOKUP('기초 자료 입력'!D28,데이터!$A$8:$E$139,2,0)),"",VLOOKUP('기초 자료 입력'!D28,데이터!$A$8:$E$139,2,0)) -> LED투광등기구 ARENA-600(3000K) 600W | F38: =IF('기초 자료 입력'!F28="","",'기초 자료 입력'!F28) -> 개 | H38: =IF('기초 자료 입력'!G28="","",'기초 자료 입력'!G28) -> 28 | I38: =IF('기초 자료 입력'!E28="","",'기초 자료 입력'!E28) -> 2950000 | J38: =IF(B38="","",H38*I38) -> 82600000 | O38: =IF(D38="","","대한민국") -> 대한민국
I39: 물 품 대 | J39: =SUM(J36:N38)/1.1 -> 2.2527273e+08
I40: 부 가 세 | J40: =J39*0.1 -> 22527273
I41: 합 계 | J41: =J39+J40 -> 2.478e+08
A42: 하자보수보증금 수납필 | D42: 󰄫 | I42: 세금계산서 접수필 | K42: 󰄫
A43: =_xlfn.CONCAT("사 업 명 : ",'기초 자료 입력'!$D$7:$I$7) -> 사 업 명 : 울산공항 계류장조명등 개선공사 관급자재 구매

Sheet 검수내역서
A2: 물 품 검 사 (수) 내 역 서
A3: ='기초 자료 입력'!B7&" :" -> 계약건명 : | B3: ='기초 자료 입력'!$D$7 -> 울산공항 계류장조명등 개선공사 관급자재 구매
A4: 금회 검수 금액 | C4: =공문!C13 -> #NAME?
A5: 품목번호 | B5: 물품명 | C5: 단위 | D5: 단가 (원) | E5: 계약상의 수 량 | F5: 전회까지의 검사(수)량 | G5: 금 회 검사(수)량 | H5: 비고
B6: 규격명
A7: 1 | B7: ='기초 자료 입력'!$L$26 -> 투광조명 | C7: ='기초 자료 입력'!F26 -> 개 | D7: ='기초 자료 입력'!$E$26 -> 2950000 | E7: ='기초 자료 입력'!$G$26 -> 28 | F7: - | G7: =E7 -> 28
B8: ='기초 자료 입력'!$K$26 -> LED투광등기구 ARENA-600(3000K) 600W
A9: =IF(B9="","",A7+1) -> 2 | B9: =IF('기초 자료 입력'!$L$27="","",'기초 자료 입력'!$L$27) -> 투광조명 | C9: =IF('기초 자료 입력'!F27="","",'기초 자료 입력'!F27) -> 개 | D9: =IF('기초 자료 입력'!$E$27="","",'기초 자료 입력'!$E$27) -> 2950000 | E9: =IF('기초 자료 입력'!$G$27="","",'기초 자료 입력'!$G$27) -> 28 | F9: =IF(B9="","","-") -> - | G9: =E9 -> 28
B10: =IF('기초 자료 입력'!$K$27="","",'기초 자료 입력'!$K$27) -> LED투광등기구 ARENA-600(3000K) 600W
A11: =IF(B11="","",A9+1) -> 3 | B11: =IF('기초 자료 입력'!$L$28="","",'기초 자료 입력'!$L$28) -> 투광조명 | C11: =IF('기초 자료 입력'!F28="","",'기초 자료 입력'!F28) -> 개 | D11: =IF('기초 자료 입력'!$E$28="","",'기초 자료 입력'!$E$28) -> 2950000 | E11: =IF('기초 자료 입력'!$G$28="","",'기초 자료 입력'!$G$28) -> 28 | F11: =IF(B11="","","-") -> - | G11: =E11 -> 28
B12: =IF('기초 자료 입력'!$K$28="","",'기초 자료 입력'!$K$28) -> LED투광등기구 ARENA-600(3000K) 600W
A13: =IF(B13="","",A11+1) -> 4 | B13: =IF('기초 자료 입력'!$L$29="","",'기초 자료 입력'!$L$29) -> 투광조명 | C13: =IF('기초 자료 입력'!F29="","",'기초 자료 입력'!F29) -> 개 | D13: =IF('기초 자료 입력'!$E$29="","",'기초 자료 입력'!$E$29) -> 2950000 | E13: =IF('기초 자료 입력'!$G$29="","",'기초 자료 입력'!$G$29) -> 28 | F13: =IF(B13="","","-") -> - | G13: =E13 -> 28
B14: =IF('기초 자료 입력'!$K$29="","",'기초 자료 입력'!$K$29) -> LED투광등기구 ARENA-600(3000K) 600W

Sheet 물납확인서
B1: 물 품 납 품 확 인 서
B2: ='기초 자료 입력'!B11&" :" -> 납품요구번호 : | C2: ='기초 자료 입력'!$D$11 -> R26TB01782064-00
B3: 계 약 건 명 : | C3: ='기초 자료 입력'!$D$7 -> 울산공항 계류장조명등 개선공사 관급자재 구매
B4: 계 약 일 자 : | C4: ='기초 자료 입력'!$D$9 -> 46120
B5: 납 품 기 한 : | C5: ='기초 자료 입력'!$D$12 -> 46196
B7: *납품내역
B8: 품명 | D8: 규격 | G8: 단위 | H8: 수량 | I8: 비고
B9: ='기초 자료 입력'!D26 -> ARENA-600(3000K) | D9: ='기초 자료 입력'!K26 -> LED투광등기구 ARENA-600(3000K) 600W | G9: ='기초 자료 입력'!F26 -> 개 | H9: ='기초 자료 입력'!G26 -> 28 | I9: =IF(B9="","","납품장소 하차도") -> 납품장소 하차도
B10: =IF('기초 자료 입력'!D27="","",'기초 자료 입력'!D27) -> ARENA-600(3000K) | D10: =IF('기초 자료 입력'!K27="","",'기초 자료 입력'!K27) -> LED투광등기구 ARENA-600(3000K) 600W | G10: =IF('기초 자료 입력'!F27="","",'기초 자료 입력'!F27) -> 개 | H10: =IF('기초 자료 입력'!G27="","",'기초 자료 입력'!G27) -> 28 | I10: =IF(B10="","","납품장소 하차도") -> 납품장소 하차도
B11: =IF('기초 자료 입력'!D28="","",'기초 자료 입력'!D28) -> ARENA-600(3000K) | D11: =IF('기초 자료 입력'!K28="","",'기초 자료 입력'!K28) -> LED투광등기구 ARENA-600(3000K) 600W | G11: =IF('기초 자료 입력'!F28="","",'기초 자료 입력'!F28) -> 개 | H11: =IF('기초 자료 입력'!G28="","",'기초 자료 입력'!G28) -> 28 | I11: =IF(B11="","","납품장소 하차도") -> 납품장소 하차도
B12: =IF('기초 자료 입력'!D29="","",'기초 자료 입력'!D29) -> ARENA-600(3000K) | D12: =IF('기초 자료 입력'!K29="","",'기초 자료 입력'!K29) -> LED투광등기구 ARENA-600(3000K) 600W | G12: =IF('기초 자료 입력'!F29="","",'기초 자료 입력'!F29) -> 개 | H12: =IF('기초 자료 입력'!G29="","",'기초 자료 입력'!G29) -> 28 | I12: =IF(B12="","","납품장소 하차도") -> 납품장소 하차도
B13: =IF('기초 자료 입력'!D30="","",'기초 자료 입력'!D30) | D13: =IF('기초 자료 입력'!K30="","",'기초 자료 입력'!K30) | G13: =IF('기초 자료 입력'!F30="","",'기초 자료 입력'!F30) | H13: =IF('기초 자료 입력'!G30="","",'기초 자료 입력'!G30) | I13: =IF(B13="","","납품장소 하차도")
B14: =IF('기초 자료 입력'!D31="","",'기초 자료 입력'!D31) | D14: =IF('기초 자료 입력'!K31="","",'기초 자료 입력'!K31) | G14: =IF('기초 자료 입력'!F31="","",'기초 자료 입력'!F31) | H14: =IF('기초 자료 입력'!G31="","",'기초 자료 입력'!G31) | I14: =IF(B14="","","납품장소 하차도")
B18: ='기초 자료 입력'!D14 -> 46195
F20: 납품자
F21: 주소 : | G21: 전남 장성군 동화면 전자농공단지2길 55
F22: 업체명 : | G22: 주식회사 매그나텍
F23: 대표자 : | G23: 박 선 후 | I23: (인)
F27: 인수자
F28: 주소 :
F29: 업체명 :
F30: 대표자 : | I30: (인)

Sheet 사진대지
A1: 사 진 대 지 | I1: 그림작업 완료
A4: ='기초 자료 입력'!$D$7 -> 울산공항 계류장조명등 개선공사 관급자재 구매
C7: ='기초 자료 입력'!$D$14 -> 46195
A9: 납 품 사 진
B10: 사업명 | D10: =A4 -> 울산공항 계류장조명등 개선공사 관급자재 구매
B11: 납품기한 | D11: ='기초 자료 입력'!D12 -> 46196
B12: 장 소 | D12: 수요기관 지정장소
B17: 제품 사진
B22: 제품 사진
B27: 제품 사진
B32: 제품 사진
B37: 제품 사진
B42: 제품 사진
B47: 제품 사진
B52: 제품 사진
B57: 제품 사진
